Workbook

Sheet How to use
A1: GRAPES manual update worklist
A2: Built October 12, 2026 from the GRAPES Search+ site data (407 listings).
A4: How to use
A5: 1. Work down the Worklist tab in order. It is sorted by priority, then by the soonest estimated deadline.
A6: 2. Open the official link, find the current details, and update the record in the GRAPES backend.
A7: 3. Fill in the yellow columns (New deadline through Date checked). Leave a cell blank if nothing changed.
A8: 4. Pick a Status from the dropdown. The Summary tab tracks progress automatically.
A9: 5. Always paste the page you used in Source link. These answers will be the test set for the AI agent pilot.
A11: Columns
A12: Grey/blue columns come from the site data. Do not edit them.
A13: Yellow columns are yours to fill in.
A14: "Estimated next deadline" rolls the last known deadline forward a year. It is a guess to help prioritize, not a confirmed date.
... A29: Example of a completed row (yellow columns)
A30: New deadline | B30: New amount | C30: Source link | D30: Status | E30: Notes | F30: Checked by | G30: Date checked
A31: 46327 | B31: $30,000 stipend | C31: https://www.lbi.org/about/fellowships/lbi-daad-fellowships/ | D31: Updated | E31: Second deadline May 1 for spring cycle | F31: DW | G31: 46308

Sheet Worklist
A1: Priority | B1: Record # | C1: Title | D1: Sponsor | E1: Site status | F1: Season | G1: Deadline on file | H1: Estimated next deadline | I1: Days left | J1: Amount on file | K1: Official link | L1: New deadline | M1: New amount | N1: Source link | O1: Status | P1: Notes | Q1: Checked by | R1: Date checked
A2: 1 - Check now | B2: 712 | C2: Penn Postdoctoral Fellowships for Academic Diversity (Provost's Postdoctoral Fellowship) | D2: University of Pennsylvania (UPenn) | E2: Unverified | F2: Fall | G2: 45943 | H2: 46308 | I2: =IF(H2="","",H2-TODAY()) -> 1 | J2: $68,300 stipend in year one (increasing $2,000/year), plus a $7,000/year research and travel allowance and up to $5,000 relocation allowance | K2: Open page
A3: 1 - Check now | B3: 99 | C3: Fellowship in History of Art and Visual Culture | D3: The Metropolitan Museum of Art | E3: Unverified | F3: Fall | G3: 45947 | H3: 46312 | I3: =IF(H3="","",H3-TODAY()) -> 5 | J3: $53,000 (junior fellows) or $63,000 (senior fellows), plus a $6,000 travel stipend | K3: Open page
A4: 1 - Check now | B4: 1119 | C4: Leonard A. Lauder Fellowships in Modern Art | D4: Leonard A. Lauder Research Center for Modern Art | E4: Verified | F4: Fall | G4: 45947 | H4: 46312 | I4: =IF(H4="","",H4-TODAY()) -> 5 | J4: $6,000 travel stipend; additional stipend varies by fellowship type | K4: Open page
A5: 1 - Check now | B5: 545 | C5: Institute of European Studies (IES) & Center for German and European Studies CGES (General) Predissertation & Dissertation Fellowships | D5: University of California (UC), Berkeley | E5: Verified | F5: Winter | G5: 45962 | H5: 46327 | I5: =IF(H5="","",H5-TODAY()) -> 20 | J5: $3,000-$5,000 | K5: Open page
A6: 1 - Check now | B6: 309 | C6: Society of Exploration Geophysicists (SEG) Foundation Scholarships | D6: Society of Exploration Geophysicists (SEG) | E6: Verified | F6: Winter | G6: 45962 | H6: 46327 | I6: =IF(H6="","",H6-TODAY()) -> 20 | J6: $500 - $10,000 per year | K6: Open page
A7: 1 - Check now | B7: 34 | C7: Career Development Program (CDP) | D7: Leukemia and Lymphoma Society (LLS) | E7: Verified | F7: Fall | G7: 45976 | H7: 46341 | I7: =IF(H7="","",H7-TODAY()) -> 34 | J7: $65,000-$75,000/year | K7: Open page
A8: 1 - Check now | B8: 1107 | C8: NISO Plus Scholarship Award | D8: NISO | E8: Unverified | F8: Fall | G8: 45985 | H8: 46350 | I8: =IF(H8="","",H8-TODAY()) -> 43 | K8: Open page
A9: 1 - Check now | B9: 1120 | C9: Lafayette Fellowship | D9: French Embassy in the United States | E9: Verified | F9: Fall | G9: 45991 | H9: 46356 | I9: =IF(H9="","",H9-TODAY()) -> 49 | J9: Full funding for one year of master's study | K9: Open page
A10: 1 - Check now | B10: 914 | C10: Center for Engaged Scholarship Dissertation Fellowships | D10: The Center for Engaged Scholarship | E10: Verified | F10: Fall | G10: 45992 | H10: 46357 | I10: =IF(H10="","",H10-TODAY()) -> 50 | J10: $25,000 over 9 months | K10: Open page
A11: 1 - Check now | B11: 198 | C11: Kate Neal Kinley Memorial Fellowship | D11: University of Illinois Urbana-Champaign, College of Fine and Applied Arts | E11: Unverified | F11: Winter | G11: 45992 | H11: 46357 | I11: =IF(H11="","",H11-TODAY()) -> 50 | J11: $20,000 (art/design, dance, music, or theatre award) | K11: Open page
A12: 1 - Check now | B12: 1069 | C12: Postdoctoral Fellow in Conservation Science | D12: Getty Conservation Institute | E12: Unverified | F12: Winter | G12: 45992 | H12: 46357 | I12: =IF(H12="","",H12-TODAY()) -> 50 | J12: Annual stipend, health insurance, study-trip allowance, and Getty scholar housing (specific dollar amount not stated) | K12: Open page
A13: 1 - Check now | B13: 668 | C13: Summer Student Fellowships | D13: Parkinson's Disease Foundation (PDF) | E13: Verified | F13: Fall | G13: 45995 | H13: 46360 | I13: =IF(H13="","",H13-TODAY()) -> 53 | J13: $4,000 (plus optional $1,000 travel) | K13: Open page
A14: 1 - Check now | B14: 188 | C14: S.V. Ciriacy-Wantrup Postdoctoral Fellowships in Natural Resource Economics and Political Economy | D14: University of California (UC), Berkeley | E14: Unverified | F14: Fall | G14: 46003 | H14: 46368 | I14: =IF(H14="","",H14-TODAY()) -> 61 | J14: $69,073–$77,030 annually | K14: Open page
A15: 1 - Check now | B15: 140 | C15: Energy Fellowship Program | D15: Link Foundation | E15: Verified | F15: Winter | G15: 46005 | H15: 46370 | I15: =IF(H15="","",H15-TODAY()) -> 63 | J15: $35,000/year for two years ($70,000 total) | K15: Open page
A16: 1 - Check now | B16: 726 | C16: Davis Fellows for Peace | D16: Middlebury College | E16: Verified | F16: Fall | G16: 46006 | H16: 46371 | I16: =IF(H16="","",H16-TODAY()) -> 64 | J16: Full tuition, housing, and food for summer | K16: Open page
A17: 1 - Check now | B17: 510 | C17: Short-Term Fellowships | D17: John Carter Brown Library | E17: Unverified | F17: Spring | G17: 46012 | H17: 46377 | I17: =IF(H17="","",H17-TODAY()) -> 70 | J17: Varies by fellowship type | K17: Open page
A18: 1 - Check now | B18: 304 | C18: Harvard Program on U.S.-Japan Relations Postdoctoral Fellowships | D18: Harvard University, Program on U.S.- Japan Relations | E18: Unverified | F18: Fall | G18: 46021 | H18: 46386 | I18: =IF(H18="","",H18-TODAY()) -> 79 | J18: Year-long stipend (commencing August or September 2026) | K18: Open page
A19: 1 - Check now | B19: 396 | C19: Goldstine Fellowship | D19: IBM Thomas J. Watson Research Center, Business Analytics and Mathematical Sciences Dept. | E19: Unverified | F19: Fall | G19: 46022 | H19: 46387 | I19: =IF(H19="","",H19-TODAY()) -> 80 | J19: Competitive postdoctoral salary and benefits | K19: Open page
A20: 1 - Check now | B20: 1112 | C20: Roe L. Johns Student Travel Grant | D20: Association for Education Finance & Policy (AEFP) | E20: Unverified | F20: Winter | G20: 46022 | H20: 46387 | I20: =IF(H20="","",H20-TODAY()) -> 80 | J20: $500 | K20: Open page
... A38: 2 - Next | B38: 721 | C38: Josephine de Karman Fellowship | D38: Josephine De Karman Fellowship Trust | E38: Verified | F38: Winter | G38: 46051 | H38: 46416 | I38: =IF(H38="","",H38-TODAY()) -> 109 | J38: $28,000 | K38: Open page
A39: 2 - Next | B39: 686 | C39: NASA Space Technology Graduate Research Opportunities (NSTGRO) | D39: National Aeronautics and Space Administration (NASA) | E39: Unverified | F39: Winter | G39: 46051 | H39: 46416 | I39: =IF(H39="","",H39-TODAY()) -> 109 | K39: Open page
A40: 2 - Next | B40: 895 | C40: Taiwan Studies Graduate Research Fellowship | D40: Taiwan Ministry of Education / Taipei Economic and Cultural Office in Los Angeles | E40: Unverified | F40: Winter | G40: 46052 | H40: 46417 | I40: =IF(H40="","",H40-TODAY()) -> 110 | K40: Open page
A41: 2 - Next | B41: 1110 | C41: Applied Machine Learning Summer Research Fellowship | D41: Los Alamos National Laboratory (LANL) | E41: Unverified | F41: Winter | G41: 46053 | H41: 46418 | I41: =IF(H41="","",H41-TODAY()) -> 111 | J41: Paid fellowship plus travel reimbursement | K41: Open page
A42: 2 - Next | B42: 708 | C42: American Nuclear Society Scholarships | D42: American Nuclear Society (ANS) | E42: Verified | F42: Winter | G42: 46054 | H42: 46419 | I42: =IF(H42="","",H42-TODAY()) -> 112 | J42: $1,000–$5,000 depending on scholarship | K42: Open page
A43: 2 - Next | B43: 1050 | C43: Clark Bibliographical Fellowship | D43: William Andrews Clark Memorial Library | E43: Verified | F43: Winter | G43: 46054 | H43: 46419 | I43: =IF(H43="","",H43-TODAY()) -> 112 | J43: $12,000 for 3 months | K43: Open page
A44: 2 - Next | B44: 794 | C44: Clark Dissertation Fellowships | D44: UCLA Center for 17th & 18th Century Studies | E44: Verified | F44: Winter | G44: 46054 | H44: 46419 | I44: =IF(H44="","",H44-TODAY()) -> 112 | J44: $36,000 | K44: Open page
A45: 2 - Next | B45: 1049 | C45: Clark Predoctoral Fellowship | D45: William Andrews Clark Memorial Library | E45: Verified | F45: Winter | G45: 46054 | H45: 46419 | I45: =IF(H45="","",H45-TODAY()) -> 112 | J45: $4,000/month for 1–3 months | K45: Open page
A46: 2 - Next | B46: 1051 | C46: Clark Short-Term Fellowships | D46: William Andrews Clark Memorial Library | E46: Verified | F46: Winter | G46: 46054 | H46: 46419 | I46: =IF(H46="","",H46-TODAY()) -> 112 | J46: $4,000/month for 1–3 months | K46: Open page
A47: 2 - Next | B47: 468 | C47: Alvin H Johnson 50 Dissertation Fellowships | D47: American Musicological Society (AMS) | E47: Verified | F47: Spring | G47: 46055 | H47: 46420 | I47: =IF(H47="","",H47-TODAY()) -> 113 | J47: $25,000 for one year | K47: Open page
A48: 2 - Next | B48: 1019 | C48: Charles F. Scott Fellowship | D48: UCLA Graduate Division | E48: Verified | F48: Winter | G48: 46066 | H48: 46431 | I48: =IF(H48="","",H48-TODAY()) -> 124 | J48: Up to $15,000 | K48: Open page
A49: 2 - Next | B49: 772 | C49: Dr. Ursula Mandel Scholarship | D49: UCLA Graduate Division | E49: Verified | F49: Winter | G49: 46066 | H49: 46431 | I49: =IF(H49="","",H49-TODAY()) -> 124 | J49: $15,000 in fees | K49: Open page
A50: 2 - Next | B50: 769 | C50: Gold Shield Alumnae of UCLA | D50: UCLA Division of Graduate Education | E50: Unverified | F50: Winter | G50: 46066 | H50: 46431 | I50: =IF(H50="","",H50-TODAY()) -> 124 | K50: Open page
A51: 2 - Next | B51: 763 | C51: Graduate Research Mentorship (GRM) Program | D51: UCLA Graduate Division | E51: Verified | F51: Winter | G51: 46066 | H51: 46431 | I51: =IF(H51="","",H51-TODAY()) -> 124 | J51: $30,000 | K51: Open page
A52: 2 - Next | B52: 762 | C52: Graduate Summer Research Mentorship (GSRM) Program | D52: UCLA Graduate Division | E52: Verified | F52: Winter | G52: 46066 | H52: 46431 | I52: =IF(H52="","",H52-TODAY()) -> 124 | J52: Summer support (varies) | K52: Open page
A53: 2 - Next | B53: 774 | C53: Paulson Scholarship Fund | D53: UCLA Graduate Division | E53: Verified | F53: Winter | G53: 46066 | H53: 46431 | I53: =IF(H53="","",H53-TODAY()) -> 124 | J53: Up to $6,000 | K53: Open page
A54: 2 - Next | B54: 782 | C54: UCLA Faculty Women's Club (FWC) Scholarship | D54: UCLA Division of Graduate Education | E54: Unverified | F54: Winter | G54: 46066 | H54: 46431 | I54: =IF(H54="","",H54-TODAY()) -> 124 | K54: Open page
A55: 2 - Next | B55: 778 | C55: Werner R. Scott Fund | D55: UCLA Graduate Division | E55: Verified | F55: Winter | G55: 46066 | H55: 46431 | I55: =IF(H55="","",H55-TODAY()) -> 124 | J55: $8,000 | K55: Open page
A56: 2 - Next | B56: 775 | C56: Will Rogers Memorial Fellowship | D56: UCLA Graduate Division | E56: Verified | F56: Winter | G56: 46066 | H56: 46431 | I56: =IF(H56="","",H56-TODAY()) -> 124 | J56: $10,000 | K56: Open page
A57: 2 - Next | B57: 920 | C57: Fellowships for Study in Quebec | D57: Society of French and Francophone Teachers of America (SPFFA) | E57: Verified | F57: Spring | G57: 46068 | H57: 46433 | I57: =IF(H57="","",H57-TODAY()) -> 126 | J57: $1,500 - $25,000 (or $4,000 for summer Quebec programs) | K57: Open page
...

Sheet Summary
A1: Progress
A3: Priority | B3: Listings | C3: Checked | D3: Remaining | E3: % done
A4: 1 - Check now | B4: =COUNTIF(Worklist!$A$2:$A$408,A4) -> 24 | C4: =COUNTIFS(Worklist!$A$2:$A$408,A4,Worklist!$O$2:$O$408,"<>") -> 0 | D4: =B4-C4 -> 24 | E4: =IF(B4=0,0,C4/B4) -> 0
A5: 2 - Next | B5: =COUNTIF(Worklist!$A$2:$A$408,A5) -> 77 | C5: =COUNTIFS(Worklist!$A$2:$A$408,A5,Worklist!$O$2:$O$408,"<>") -> 0 | D5: =B5-C5 -> 77 | E5: =IF(B5=0,0,C5/B5) -> 0
A6: 3 - Later | B6: =COUNTIF(Worklist!$A$2:$A$408,A6) -> 86 | C6: =COUNTIFS(Worklist!$A$2:$A$408,A6,Worklist!$O$2:$O$408,"<>") -> 0 | D6: =B6-C6 -> 86 | E6: =IF(B6=0,0,C6/B6) -> 0
A7: 4 - Find a date | B7: =COUNTIF(Worklist!$A$2:$A$408,A7) -> 65 | C7: =COUNTIFS(Worklist!$A$2:$A$408,A7,Worklist!$O$2:$O$408,"<>") -> 0 | D7: =B7-C7 -> 65 | E7: =IF(B7=0,0,C7/B7) -> 0
A8: 5 - Rolling | B8: =COUNTIF(Worklist!$A$2:$A$408,A8) -> 26 | C8: =COUNTIFS(Worklist!$A$2:$A$408,A8,Worklist!$O$2:$O$408,"<>") -> 0 | D8: =B8-C8 -> 26 | E8: =IF(B8=0,0,C8/B8) -> 0
A9: 6 - Current | B9: =COUNTIF(Worklist!$A$2:$A$408,A9) -> 129 | C9: =COUNTIFS(Worklist!$A$2:$A$408,A9,Worklist!$O$2:$O$408,"<>") -> 0 | D9: =B9-C9 -> 129 | E9: =IF(B9=0,0,C9/B9) -> 0
A10: Total | B10: =SUM(B4:B9) -> 407 | C10: =SUM(C4:C9) -> 0 | D10: =SUM(D4:D9) -> 407 | E10: =IF(B10=0,0,C10/B10) -> 0
A12: By status
A13: Status | B13: Count
A14: Updated | B14: =COUNTIF(Worklist!$O$2:$O$408,A14) -> 0
A15: No change needed | B15: =COUNTIF(Worklist!$O$2:$O$408,A15) -> 0
A16: Not posted yet | B16: =COUNTIF(Worklist!$O$2:$O$408,A16) -> 0
A17: Discontinued / paused | B17: =COUNTIF(Worklist!$O$2:$O$408,A17) -> 0
A18: Link broken - new link found | B18: =COUNTIF(Worklist!$O$2:$O$408,A18) -> 0
A19: Link broken - not found | B19: =COUNTIF(Worklist!$O$2:$O$408,A19) -> 0
